I'm sorry, but an uncaught exception occurred.

While running game code:
  File "game/locations.rpy", line 138, in script call
    call tenth_round
  File "game/utilities.rpy", line 1077, in script call
    call sleepover
  File "game/sleepover.rpy", line 637, in script call
    call remove_Girl(temp_Girls[0])
  File "game/utilities.rpy", line 669, in script
    while Girls_to_remove:
  File "game/utilities.rpy", line 669, in <module>
    while Girls_to_remove:
NameError: name 'Girls_to_remove' is not defined

-- Full Traceback ------------------------------------------------------------

Full traceback:
  File "game/locations.rpy", line 138, in script call
    call tenth_round
  File "game/utilities.rpy", line 1077, in script call
    call sleepover
  File "game/sleepover.rpy", line 637, in script call
    call remove_Girl(temp_Girls[0])
  File "game/utilities.rpy", line 669, in script
    while Girls_to_remove:
  File "renpy/ast.py", line 1841, in execute
    if renpy.python.py_eval(self.condition):
  File "renpy/python.py", line 2276, in py_eval
    return py_eval_bytecode(code, globals, locals)
  File "renpy/python.py", line 2269, in py_eval_bytecode
    return eval(bytecode, globals, locals)
  File "game/utilities.rpy", line 669, in <module>
    while Girls_to_remove:
NameError: name 'Girls_to_remove' is not defined

Windows-10-10.0.19041
Ren'Py 7.4.11.2266
Rogue-Like Chonky Mod 0.2h
Wed Jun 22 04:46:53 2022
